Workbook

Sheet Summary 

Sheet Dashboard 
R10: EBITDA Sensitivity (₹ Cr): Volume Growth vs. COGS %
R11: 7436.1691 | S11: 0.43 | T11: 0.45 | U11: 0.47 | V11: 0.49 | W11: 0.51
R12: 0.08 | S12: 7247.3398 | T12: 6667.5527 | U12: 6087.7655 | V12: 5507.9783 | W12: 4928.1911
R13: 0.1 | S13: 7657.472 | T13: 7044.8742 | U13: 6432.2765 | V13: 5819.6787 | W13: 5207.0809
R14: 0.12 | S14: 8082.7925 | T14: 7436.1691 | U14: 6789.5457 | V14: 6142.9223 | W14: 5496.2989
R15: 0.14 | S15: 8523.5775 | T15: 7841.6913 | U15: 7159.8051 | V15: 6477.9189 | W15: 5796.0327
R16: 0.16 | S16: 8980.1032 | T16: 8261.695 | U16: 7543.2867 | V16: 6824.8784 | W16: 6106.4702

Sheet Ratio Analysis
B2: Particulars | C2: Historical years | F2: Forecasted Years
C3: 45291 | D3: =EDATE(C3,12) -> 45657 | E3: =EDATE(D3,12) -> 46022 | F3: =EDATE(E3,12) -> 46387 | G3: =EDATE(F3,12) -> 46752 | H3: =EDATE(G3,12) -> 47118
B5: Revenue Growth (YoY %) | C5: =('Raw Data '!E5/'Raw Data '!D5)-1 -> 0.21782506 | D5: =('Raw Data '!F5/'Raw Data '!E5)-1 -> 0.24715912 | E5: =('Raw Data '!G5/'Raw Data '!F5)-1 -> 0.083853926 | F5: =('Calculations '!C6/'Raw Data '!G5)-1 -> 0.1424 | G5: =('Calculations '!D6/'Calculations '!C6)-1 -> 0.1424 | H5: =('Calculations '!E6/'Calculations '!D6)-1 -> 0.1424
B6: EBITDA Growth (YoY %) | C6: =('Raw Data '!E9/'Raw Data '!D9)-1 -> 0.63145823 | D6: =('Raw Data '!F9/'Raw Data '!E9)-1 -> 0.33502967 | E6: =('Raw Data '!G9/'Raw Data '!F9)-1 -> 0.084870778 | F6: =('Calculations '!C17/'Raw Data '!G9)-1 -> 0.11287695 | G6: =('Calculations '!D17/'Calculations '!C17)-1 -> 0.1424 | H6: =('Calculations '!E17/'Calculations '!D17)-1 -> 0.1424
B7: EBITDA Margin (%) | C7: ='Raw Data '!E9/'Raw Data '!E5 -> 0.22035483 | D7: ='Raw Data '!F9/'Raw Data '!F5 -> 0.23588028 | E7: ='Raw Data '!G9/'Raw Data '!G5 -> 0.23610157 | F7: ='Calculations '!C17/'Calculations '!C6 -> 0.23 | G7: ='Calculations '!D17/'Calculations '!D6 -> 0.23 | H7: ='Calculations '!E17/'Calculations '!E6 -> 0.23
B8: Operating Leverage | C8: =C6/C5 -> 2.8989237 | D8: =D6/D5 -> 1.3555222 | E8: =E6/E5 -> 1.0121265 | F8: =F6/F5 -> 0.79267521 | G8: =G6/G5 -> 1 | H8: =H6/H5 -> 1
B9: Debt-to-equity | C9: ='Data Sheet '!I59/('Data Sheet '!I57+'Data Sheet '!I58) -> 0.7830044 | D9: ='Data Sheet '!J59/('Data Sheet '!J57+'Data Sheet '!J58) -> 0.17015526 | E9: ='Data Sheet '!K59/('Data Sheet '!K57+'Data Sheet '!K58) -> 0.12810759 | F9: N/a | G9: N/a | H9: N/a
B10: Return on Equity | C10: ='Data Sheet '!I30/('Data Sheet '!I57+'Data Sheet '!I58) -> 0.29639155 | D10: ='Data Sheet '!J30/('Data Sheet '!J57+'Data Sheet '!J58) -> 0.15621051 | E10: ='Data Sheet '!K30/('Data Sheet '!K57+'Data Sheet '!K58) -> 0.1550915 | F10: N/a | G10: N/a | H10: N/a

Sheet Assumptions
B3: Revenue Drivers (Operational Inputs)
B4: Assumption Metric | C4: Base Case Value | D4: Notes
B5: Volume Growth Rate (% YoY) | C5: 0.12 | D5: Driven by rural expansion and international additions (e.g., South Africa/DRC).
B6: Net Realization Growth (% YoY | C6: 0.02 | D6: Driven by price adjustments and mix shift to higher-realization SKUs
B8: Expense Drivers (% of Operational Revenue)
B9: Assumption Metric | C9: Base Case Value | D9: Notes
B10: Cogs/Raw Material Margin | C10: 0.45 | D10: Represents sugar, PET bottle resin, and packaging materials
B11: Employee Costs | C11: 0.11 | D11: Historical baseline for factory and distribution workforce.
B12: Other Operating Expense | C12: 0.21 | D12: Freight, logistics, power, fuel, and marketing expenses.
B13: Effective Tax Rate | C13: 0.25 | D13: Standard Corporate Tax Rate in India.

Sheet Calculations 
B2: Section A: Revenue Drivers & Forecast | C2: 46387 | D2: =EDATE(C2,12) -> 46752 | E2: =EDATE(D2,12) -> 47118
B3: Particulars
B4: Forecasted Sales Volume (Mn Cases): | C4: ='Raw Data '!G3*(1+Assumptions!C5) -> 1358.56 | D4: =C4*(1+Assumptions!C5) -> 1521.5872 | E4: =D4*(1+Assumptions!C5) -> 1704.1777
B5: Forecasted Realization per Case (₹): | C5: ='Raw Data '!G4*(1+Assumptions!C6) -> 182.35018 | D5: =C5*(1+Assumptions!C6) -> 185.99719 | E5: =D5*(1+Assumptions!C6) -> 189.71713
B6: Forecasted Total Revenue (₹ Crores): | C6: =C4*C5/10 -> 24773.367 | D6: =D4*D5/10 -> 28301.094 | E6: =E4*E5/10 -> 32331.17
B7: Section B: Price vs. Volume Variance Analysis
B8: Particulars
B9: Volume Variance | C9: =('Raw Data '!G3-'Raw Data '!F3)*'Raw Data '!F4 -> 15842.356 | D9: =(D4-C4)*C5 -> 29728.04 | E9: =(E4-D4)*D5 -> 33961.313
B10: Price/Realization Variance | C10: =('Raw Data '!G4-'Raw Data '!F4)*'Raw Data '!G3 -> 934.84368 | D10: =(D5-C5)*D4 -> 5549.2341 | E10: =(E5-D5)*E4 -> 6339.4451
B11: Total Revenue Variance | C11: =C9+C10 -> 16777.2 | D11: =D9+D10 -> 35277.274 | E11: =E9+E10 -> 40300.758
B12: Section C: Expense Forecasting & EBITDA Calculation.
B13: Particulars
B14: Forecasted COGS (Raw Materials): | C14: =C6*Assumptions!C10 -> 11148.015 | D14: =$D$6*Assumptions!C10 -> 12735.492 | E14: =$E$6*Assumptions!C10 -> 14549.026
B15: Forecasted Employee Costs: | C15: =C6*Assumptions!C11 -> 2725.0703 | D15: =$D$6*Assumptions!C11 -> 3113.1204 | E15: =$E$6*Assumptions!C11 -> 3556.4287
B16: Forecasted Other Operating Expenses: | C16: =C6*Assumptions!C12 -> 5202.407 | D16: =$D$6*Assumptions!C12 -> 5943.2298 | E16: =$E$6*Assumptions!C12 -> 6789.5457
B17: Forecasted EBITDA (Operating Profit): | C17: =C6-(C14+C15+C16) -> 5697.8743 | D17: =D6-(D14+D15+D16) -> 6509.2516 | E17: =E6-(E14+E15+E16) -> 7436.1691
B18: EBITDA Margin % | C18: =C17/C6 -> 0.23 | D18: =D17/D6 -> 0.23 | E18: =E17/E6 -> 0.23
C21: COGS % test values
A23: Volume Growth % test values

Sheet Raw Data 
B2: Particulars | C2: 44561 | D2: =EDATE(C2,12) -> 44926 | E2: =EDATE(D2,12) -> 45291 | F2: =EDATE(E2,12) -> 45657 | G2: =EDATE(F2,12) -> 46022
B3: Sales Volume (Million Cases) | C3: 569 | D3: 802 | E3: 913 | F3: 1124 | G3: 1213
B4: Net Realization per Case (₹) | C4: =C5/C3*10 -> 155.06555 | D4: =D5/D3*10 -> 164.25362 | E4: =E5/E3*10 -> 175.71281 | F4: =F5/F3*10 -> 178.004 | G4: =G5/G3*10 -> 178.77469
B5: Revenue from Operations | C5: ='Data Sheet '!G17 -> 8823.23 | D5: ='Data Sheet '!H17 -> 13173.14 | E5: ='Data Sheet '!I17 -> 16042.58 | F5: ='Data Sheet '!J17 -> 20007.65 | G5: ='Data Sheet '!K17 -> 21685.37
B6: Raw Material / COGS | C6: ='Data Sheet '!G18+'Data Sheet '!G19 -> 4234.1 | D6: ='Data Sheet '!H18+'Data Sheet '!H19 -> 6950.17 | E6: ='Data Sheet '!I18+'Data Sheet '!I19 -> 7573.43 | F6: ='Data Sheet '!J18+'Data Sheet '!J19 -> 9054.6 | G6: ='Data Sheet '!K18+'Data Sheet '!K19 -> 9697.61
B7: Employee Cost | C7: ='Data Sheet '!G22 -> 1015.43 | D7: ='Data Sheet '!H22 -> 1235.2 | E7: ='Data Sheet '!I22 -> 1447.18 | F7: ='Data Sheet '!J22 -> 1885.88 | G7: ='Data Sheet '!K22 -> 2201.26
B8: Other Operating Expenses | C8: ='Data Sheet '!G20+'Data Sheet '!G20+'Data Sheet '!G23+'Data Sheet '!G24 -> 2080.77 | D8: ='Data Sheet '!H20+'Data Sheet '!H20+'Data Sheet '!H23+'Data Sheet '!H24 -> 2820.96 | E8: ='Data Sheet '!I20+'Data Sheet '!I20+'Data Sheet '!I23+'Data Sheet '!I24 -> 3486.91 | F8: ='Data Sheet '!J20+'Data Sheet '!J20+'Data Sheet '!J23+'Data Sheet '!J24 -> 4347.76 | G8: ='Data Sheet '!K20+'Data Sheet '!K20+'Data Sheet '!K23+'Data Sheet '!K24 -> 4666.55
B9: Operating Profit (EBITDA) | C9: =C5- SUM(C6:C8) -> 1492.93 | D9: =D5- SUM(D6:D8) -> 2166.81 | E9: =E5- SUM(E6:E8) -> 3535.06 | F9: =F5- SUM(F6:F8) -> 4719.41 | G9: =G5- SUM(G6:G8) -> 5119.95
B10: Net Income (PAT) | C10: ='Data Sheet '!G30 -> 694.05 | D10: ='Data Sheet '!H30 -> 1497.43 | E10: ='Data Sheet '!I30 -> 2055.92 | F10: ='Data Sheet '!J30 -> 2594.63 | G10: ='Data Sheet '!K30 -> 3036.49

Sheet Data Sheet 
A1: COMPANY NAME | B1: VARUN BEVERAGES LTD | E1: =IF(B2<>B3, "A NEW VERSION OF THE WORKSHEET IS AVAILABLE", "")
A2: LATEST VERSION | B2: 2.1 | E2: PLEASE DO NOT MAKE ANY CHANGES TO THIS SHEET
A3: CURRENT VERSION | B3: 2.1
A5: META
A6: Number of shares | B6: =IF(B9>0, B9/B8, 0) -> 338.31677
A7: Face Value | B7: 2
A8: Current Price | B8: 478.1
A9: Market Capitalization | B9: 161749.25
A15: PROFIT & LOSS
A16: Report Date | B16: 42735 | C16: 43100 | D16: 43465 | E16: 43830 | F16: 44196 | G16: 44561 | H16: 44926 | I16: 45291 | J16: 45657 | K16: 46022
A17: Sales | B17: 3861.18 | C17: 4003.54 | D17: 5105.26 | E17: 7129.58 | F17: 6450.14 | G17: 8823.23 | H17: 13173.14 | I17: 16042.58 | J17: 20007.65 | K17: 21685.37
A18: Raw Material Cost | B18: 1769.74 | C18: 1883.28 | D18: 2306.5 | E18: 3363.29 | F18: 2781.1 | G18: 4134.38 | H18: 6605.66 | I18: 7489.16 | J18: 8979.66 | K18: 9706.52
A19: Change in Inventory | B19: 31.86 | C19: 73.22 | D19: 62.4 | E19: 143.86 | F19: 17.16 | G19: 99.72 | H19: 344.51 | I19: 84.27 | J19: 74.94 | K19: -8.91
A20: Power and Fuel | B20: 156.22 | C20: 160.04 | D20: 194.8 | E20: 279.06 | F20: 267 | G20: 329.93 | H20: 479.22 | I20: 550.29 | J20: 629.51 | K20: 636.56
A21: Other Mfr. Exp | B21: 154.66 | C21: 154.49 | D21: 191.58 | E21: 245.4 | F21: 264.33 | G21: 328.35 | H21: 472.05 | I21: 537.15 | J21: 680.53 | K21: 668.95
A22: Employee Cost | B22: 421.45 | C22: 463.18 | D22: 583.27 | E22: 811.58 | F22: 890.1 | G22: 1015.43 | H22: 1235.2 | I22: 1447.18 | J22: 1885.88 | K22: 2201.26
A23: Selling and admin | B23: 542.99 | C23: 525.92 | D23: 1692.78 | E23: 2369.99 | F23: 2091.63 | G23: 1358.89 | H23: 1777.38 | I23: 2253.82 | J23: 2920.33 | K23: 3250.63
A24: Other Expenses | B24: 38.47 | C24: 51.52 | D24: -837.07 | E24: -1258.2 | F24: -1041.82 | G24: 62.02 | H24: 85.14 | I24: 132.51 | J24: 168.41 | K24: 142.8
A25: Other Income | B25: 26.77 | C25: 13.86 | D25: 5.87 | E25: 46.89 | F25: -30.01 | G25: 50.89 | H25: -18.08 | I25: -4.87 | J25: 45.07 | K25: 352.35
A26: Depreciation | B26: 322.21 | C26: 346.64 | D26: 385.07 | E26: 488.63 | F26: 528.7 | G26: 531.26 | H26: 617.19 | I26: 680.91 | J26: 947.39 | K26: 1216.46
A27: Interest | B27: 434.74 | C27: 214.59 | D27: 222.8 | E27: 324.31 | F27: 293.74 | G27: 206.97 | H27: 204.09 | I27: 291.6 | J27: 482.86 | K27: 195.98
... A30: Net profit | B30: 42.38 | C30: 210.15 | D30: 292.84 | E30: 468.98 | F30: 329 | G30: 694.05 | H30: 1497.43 | I30: 2055.92 | J30: 2594.63 | K30: 3036.49
A31: Dividend Amount | C31: 45.65 | D31: 45.66 | E31: 72.17 | F31: 72.17 | G31: 108.26 | H31: 227.34 | I31: 324.8 | J31: 338.15 | K31: 507.3
A40: Quarters
A41: Report Date | B41: 45291 | C41: 45382 | D41: 45473 | E41: 45565 | F41: 45657 | G41: 45747 | H41: 45838 | I41: 45930 | J41: 46022 | K41: 46112
A42: Sales | B42: 2667.69 | C42: 4317.31 | D42: 7196.86 | E42: 4804.68 | F42: 3688.79 | G42: 5566.94 | H42: 7017.37 | I42: 4896.65 | J42: 4204.42 | K42: 6574.19
A43: Expenses | B43: 2249.4 | C43: 3328.7 | D43: 5206.18 | E43: 3653.65 | F43: 3109.5 | G43: 4303.56 | H43: 5019.78 | I43: 3750.96 | J43: 3567.76 | K43: 5049.21
A44: Other Income | B44: 9.32 | C44: 8.35 | D44: 44.03 | E44: 24.25 | F44: 44.64 | G44: 28.06 | H44: 77.16 | I44: 148.03 | J44: 99.11 | K44: 43.53
A45: Depreciation | B45: 165.97 | C45: 187.52 | D45: 242.48 | E45: 256.61 | F45: 260.78 | G45: 272.51 | H45: 306.15 | I45: 307.6 | J45: 330.2 | K45: 356.79
A46: Interest | B46: 73.66 | C46: 93.69 | D46: 129.16 | E46: 118.54 | F46: 109.01 | G46: 41.12 | H46: 36.55 | I46: 45.21 | J46: 46.69 | K46: 48.53
A47: Profit before tax | B47: 187.98 | C47: 715.75 | D47: 1663.07 | E47: 800.13 | F47: 254.14 | G47: 977.81 | H47: 1732.05 | I47: 940.91 | J47: 358.88 | K47: 1163.19
A48: Tax | B48: 44.22 | C48: 167.77 | D48: 401.24 | E48: 171.3 | F48: 58.5 | G48: 246.45 | H48: 406.55 | I48: 195.72 | J48: 98.88 | K48: 284.48
A49: Net profit | B49: 131.97 | C49: 537.27 | D49: 1252.6 | E49: 619.61 | F49: 185.15 | G49: 726.49 | H49: 1317.02 | I49: 741.19 | J49: 251.79 | K49: 872.36
A50: Operating Profit | B50: 418.29 | C50: 988.61 | D50: 1990.68 | E50: 1151.03 | F50: 579.29 | G50: 1263.38 | H50: 1997.59 | I50: 1145.69 | J50: 636.66 | K50: 1524.98
A55: BALANCE SHEET
A56: Report Date | B56: 42735 | C56: 43100 | D56: 43465 | E56: 43830 | F56: 44196 | G56: 44561 | H56: 44926 | I56: 45291 | J56: 45657 | K56: 46022
A57: Equity Share Capital | B57: 182.31 | C57: 182.59 | D57: 182.64 | E57: 288.69 | F57: 288.69 | G57: 433.03 | H57: 649.55 | I57: 649.61 | J57: 676.3 | K57: 676.4
A58: Reserves | B58: 1511.28 | C58: 1586.84 | D58: 1815.86 | E58: 3039.73 | F58: 3235.31 | G58: 3646.88 | H58: 4452.83 | I58: 6286.89 | J58: 15933.53 | K58: 18902.3
A59: Borrowings | B59: 2215.4 | C59: 2653.7 | D59: 2807.87 | E59: 3417.18 | F59: 3216.13 | G59: 3386.76 | H59: 3883.81 | I59: 5431.31 | J59: 2826.25 | K59: 2508.18
A60: Other Liabilities | B60: 915.43 | C60: 852.48 | D60: 1191.64 | E60: 1629.98 | F60: 1707.24 | G60: 2112.81 | H60: 2632.05 | I60: 2819.37 | J60: 3688.21 | K60: 3453.84
...
